old-style exception fixed in groupdata.py
